Workbook

Sheet Facturas
A1: Nº Factura | B1: Fecha | C1: Cliente | D1: Comercial | E1: Servicio | F1: Base imponible | G1: IVA | H1: Total | I1: Vencimiento | J1: Estado | K1: Fecha cobro
A2: F-2025-0001 | B2: 45659 | C2: Clínica Estética Lumen | D2: Javier Climent | E2: Mantenimiento climatización | F2: 869.59 | G2: 182.61 | H2: 1052.2 | I2: 45689 | J2: Cobrada | K2: 45689
A3: F-2025-0002 | B3: 45659 | C3: Clínica Dental Ruzafa | D3: Marcos Ibáñez | E3: Instalación eléctrica | F3: 6272.61 | G3: 1317.25 | H3: 7589.86 | I3: 45689 | J3: Cobrada | K3: 45668
A4: F-2025-0003 | B4: 45659 | C4: Hostal Ciutat Vella | D4: Sara Peris | E4: Mantenimiento climatización | F4: 266.8 | G4: 56.03 | H4: 322.83 | I4: 45689 | J4: Cobrada | K4: 45668
A5: F-2025-0004 | B5: 45659 | C5: Hostal Ciutat Vella | D5: Laura Gómez | E5: Mantenimiento climatización | F5: 725.2 | G5: 152.29 | H5: 877.49 | I5: 45689 | J5: Cobrada | K5: 45668
A6: F-2025-0005 | B6: 45660 | C6: Talleres Mecánicos Ribera | D6: Laura Gómez | E6: Instalación aire acondicionado | F6: 4272.84 | G6: 897.3 | H6: 5170.14 | I6: 45690 | J6: Cobrada | K6: 45678
A7: F-2025-0006 | B7: 45660 | C7: Talleres Mecánicos Ribera | D7: Sara Peris | E7: Instalación aire acondicionado | F7: 6327.91 | G7: 1328.86 | H7: 7656.77 | I7: 45690 | J7: Cobrada | K7: 45683
A8: F-2025-0007 | B8: 45663 | C8: Óptica Visión Clara | D8: Laura Gómez | E8: Fontanería | F8: 1812.9 | G8: 380.71 | H8: 2193.61 | I8: 45693 | J8: Cobrada | K8: 45699
A9: F-2025-0008 | B9: 45663 | C9: Supermercados La Huerta | D9: Laura Gómez | E9: Instalación eléctrica | F9: 4685.79 | G9: 984.02 | H9: 5669.81 | I9: 45693 | J9: Cobrada | K9: 45682
A10: F-2025-0009 | B10: 45663 | C10: Clínica Dental Ruzafa | D10: Laura Gómez | E10: Mantenimiento climatización | F10: 378.62 | G10: 79.51 | H10: 458.13 | I10: 45693 | J10: Cobrada | K10: 45683
A11: F-2025-0010 | B11: 45663 | C11: Hotel Marina Sol | D11: Laura Gómez | E11: Instalación aire acondicionado | F11: 4760.13 | G11: 999.63 | H11: 5759.76 | I11: 45693 | J11: Cobrada | K11: 45668
A12: F-2025-0011 | B12: 45664 | C12: Hotel Marina Sol | D12: Javier Climent | E12: Instalación aire acondicionado | F12: 4328.03 | G12: 908.89 | H12: 5236.92 | I12: 45694 | J12: Cobrada | K12: 45697
A13: F-2025-0012 | B13: 45664 | C13: Hotel Marina Sol | D13: Javier Climent | E13: Mantenimiento climatización | F13: 553.37 | G13: 116.21 | H13: 669.58 | I13: 45694 | J13: Cobrada | K13: 45702
... A125: F-2025-0124 | B125: 45698 | C125: Clínica Fisio Mestalla | D125: Sara Peris | E125: Mantenimiento climatización | F125: 547.26 | G125: 114.92 | H125: 662.18 | I125: 45728 | J125: Cobrada | K125: 45704
A126: F-2025-0125 | B126: 45698 | C126: Clínica Dental Ruzafa | D126: Sara Peris | E126: Revisión eficiencia energética | F126: 1614.41 | G126: 339.03 | H126: 1953.44 | I126: 45728 | J126: Vencida
A127: F-2025-0126 | B127: 45699 | C127: Hotel Marina Sol | D127: Laura Gómez | E127: Mantenimiento climatización | F127: 810.81 | G127: 170.27 | H127: 981.08 | I127: 45729 | J127: Cobrada | K127: 45733
A128: F-2025-0127 | B128: 45699 | C128: Pastelería Dulce Albaida | D128: Laura Gómez | E128: Instalación aire acondicionado | F128: 6566.36 | G128: 1378.94 | H128: 7945.3 | I128: 45729 | J128: Cobrada | K128: 45709
A129: F-2025-0128 | B129: 45699 | C129: Clínica Dental Ruzafa | D129: Laura Gómez | E129: Reforma de local | F129: 36708.25 | G129: 7708.73 | H129: 44416.98 | I129: 45729 | J129: Cobrada | K129: 45718
A130: F-2025-0129 | B130: 45699 | C130: Hotel Playa Gandia | D130: Laura Gómez | E130: Mantenimiento climatización | F130: 925.88 | G130: 194.43 | H130: 1120.31 | I130: 45729 | J130: Cobrada | K130: 45713
A131: F-2025-0130 | B131: 45699 | C131: Panadería Horno de Campanar | D131: Sara Peris | E131: Revisión eficiencia energética | F131: 940.78 | G131: 197.56 | H131: 1138.34 | I131: 45729 | J131: Cobrada | K131: 45738
A132: F-2025-0131 | B132: 45699 | C132: Hotel Marina Sol | D132: Laura Gómez | E132: Mantenimiento climatización | F132: 336.81 | G132: 70.73 | H132: 407.54 | I132: 45729 | J132: Cobrada | K132: 45715
A133: F-2025-0132 | B133: 45700 | C133: Academia Idiomas Albufera | D133: Sara Peris | E133: Fontanería | F133: 2195.46 | G133: 461.05 | H133: 2656.51 | I133: 45730 | J133: Cobrada | K133: 45732
A134: F-2025-0133 | B134: 45700 | C134: Hotel Marina Sol | D134: Laura Gómez | E134: Mantenimiento climatización | F134: 731.05 | G134: 153.52 | H134: 884.57 | I134: 45730 | J134: Cobrada | K134: 45723
A135: F-2025-0134 | B135: 45700 | C135: Hotel Marina Sol | D135: Sara Peris | E135: Instalación aire acondicionado | F135: 4259.39 | G135: 894.47 | H135: 5153.86 | I135: 45730 | J135: Cobrada | K135: 45719
A136: F-2025-0135 | B136: 45700 | C136: Restaurante El Palmar | D136: Sara Peris | E136: Contrato mantenimiento anual | F136: 5932.47 | G136: 1245.82 | H136: 7178.29 | I136: 45730 | J136: Cobrada | K136: 45733
A137: F-2025-0136 | B137: 45700 | C137: Colegio Sant Vicent | D137: Marcos Ibáñez | E137: Reparación urgente | F137: 137.58 | G137: 28.89 | H137: 166.47 | I137: 45730 | J137: Cobrada | K137: 45738
A138: F-2025-0137 | B138: 45700 | C138: Clínica Dental Ruzafa | D138: Marcos Ibáñez | E138: Reparación urgente | F138: 534.08 | G138: 112.16 | H138: 646.24 | I138: 45730 | J138: Cobrada | K138: 45728
... A206: F-2025-0205 | B206: 45720 | C206: Restaurante El Palmar | D206: Marcos Ibáñez | E206: Fontanería | F206: 2009.16 | G206: 421.92 | H206: 2431.08 | I206: 45750 | J206: Cobrada | K206: 45730
A207: F-2025-0206 | B207: 45720 | C207: Colegio Sant Vicent | D207: Sara Peris | E207: Instalación eléctrica | F207: 5119.38 | G207: 1075.07 | H207: 6194.45 | I207: 45750 | J207: Vencida
A208: F-2025-0207 | B208: 45720 | C208: Heladería La Alquería | D208: Javier Climent | E208: Fontanería | F208: 1843.98 | G208: 387.24 | H208: 2231.22 | I208: 45750 | J208: Cobrada | K208: 45751
A209: F-2025-0208 | B209: 45720 | C209: Hotel Marina Sol | D209: Marcos Ibáñez | E209: Fontanería | F209: 545.78 | G209: 114.61 | H209: 660.39 | I209: 45750 | J209: Cobrada | K209: 45752
A210: F-2025-0209 | B210: 45721 | C210: Imprenta Gráficas Turia | D210: Sara Peris | E210: Mantenimiento climatización | F210: 437.41 | G210: 91.86 | H210: 529.27 | I210: 45751 | J210: Cobrada | K210: 45727
A211: F-2025-0210 | B211: 45721 | C211: Óptica Visión Clara | D211: Laura Gómez | E211: Reparación urgente | F211: 717.92 | G211: 150.76 | H211: 868.68 | I211: 45751 | J211: Cobrada | K211: 45758
A212: F-2025-0211 | B212: 45721 | C212: Bodegas Requena Alta | D212: Laura Gómez | E212: Mantenimiento climatización | F212: 554.97 | G212: 116.54 | H212: 671.51 | I212: 45751 | J212: Cobrada | K212: 45727
A213: F-2025-0212 | B213: 45721 | C213: Hotel Marina Sol | D213: Sara Peris | E213: Reparación urgente | F213: 662.55 | G213: 139.14 | H213: 801.69 | I213: 45751 | J213: Cobrada | K213: 45740
A214: F-2025-0213 | B214: 45721 | C214: Asesoría Martí & Asociados | D214: Javier Climent | E214: Instalación placas solares | F214: 22726.18 | G214: 4772.5 | H214: 27498.68 | I214: 45751 | J214: Cobrada | K214: 45733
A215: F-2025-0214 | B215: 45722 | C215: Colegio Sant Vicent | D215: Laura Gómez | E215: Instalación aire acondicionado | F215: 4866.01 | G215: 1021.86 | H215: 5887.87 | I215: 45752 | J215: Cobrada | K215: 45729
A216: F-2025-0215 | B216: 45722 | C216: Colegio Sant Vicent | D216: Marcos Ibáñez | E216: Instalación aire acondicionado | F216: 4747.6 | G216: 997 | H216: 5744.6 | I216: 45752 | J216: Cobrada | K216: 45728
A217: F-2025-0216 | B217: 45722 | C217: Cárnicas del Mediterráneo | D217: Laura Gómez | E217: Reparación urgente | F217: 213.63 | G217: 44.86 | H217: 258.49 | I217: 45752 | J217: Cobrada | K217: 45730
A218: F-2025-0217 | B218: 45722 | C218: Colegio Sant Vicent | D218: Laura Gómez | E218: Instalación placas solares | F218: 10284.53 | G218: 2159.75 | H218: 12444.28 | I218: 45752 | J218: Cobrada | K218: 45753
...

Sheet Clientes
A1: Cliente | B1: CIF | C1: Sector | D1: Población | E1: Cliente desde
A2: Hotel Marina Sol | B2: B37876771 | C2: Hostelería | D2: Valencia | E2: 42714
A3: Clínica Dental Ruzafa | B3: B44077846 | C3: Salud | D3: Valencia | E3: 42863
A4: Colegio Sant Vicent | B4: B86654701 | C4: Educación | D4: Paterna | E4: 43285
A5: Supermercados La Huerta | B5: B70753282 | C5: Retail | D5: Torrent | E5: 43720
A6: Estudio Arquitectura Cabanyal | B6: B35627726 | C6: Servicios profesionales | D6: Valencia | E6: 43929
A7: Residencia Los Naranjos | B7: B81474515 | C7: Salud | D7: Alzira | E7: 44556
A8: Gimnasio Turia Fit | B8: B31308772 | C8: Deporte | D8: Valencia | E8: 44745
A9: Logística Puerto Sur | B9: B80293288 | C9: Logística | D9: Sagunto | E9: 44953
A10: Restaurante El Palmar | B10: B58441829 | C10: Hostelería | D10: Valencia | E10: 45342
A11: Centro Médico Benimaclet | B11: B56235501 | C11: Salud | D11: Valencia | E11: 42524
A12: Academia Idiomas Albufera | B12: B44420644 | C12: Educación | D12: Catarroja | E12: 43095
A13: Talleres Mecánicos Ribera | B13: B17302352 | C13: Industria | D13: Alzira | E13: 43300
... A51: Librería Papel y Tinta | B51: B35935441 | C51: Retail | D51: Valencia | E51: 44181

Sheet Gastos
A1: Fecha | B1: Proveedor | C1: Categoría | D1: Concepto | E1: Importe
A2: 45659 | B2: Climatización Distribución SL | C2: Material | D2: Material climatización | E2: 6429.75
A3: 45659 | B3: Telefonía Empresa Total | C3: Oficina | D3: Oficina telefonía | E3: 230.4
A4: 45659 | B4: Papelería Oficina Express | C4: Oficina | D4: Oficina papelería | E4: 314.06
A5: 45659 | B5: Papelería Oficina Express | C5: Oficina | D5: Oficina papelería | E5: 330.16
A6: 45659 | B6: Papelería Oficina Express | C6: Oficina | D6: Oficina papelería | E6: 204.44
A7: 45660 | B7: Climatización Distribución SL | C7: Material | D7: Material climatización | E7: 4206.86
A8: 45660 | B8: Papelería Oficina Express | C8: Oficina | D8: Oficina papelería | E8: 287.82
A9: 45660 | B9: Software Gestión Obras | C9: Software | D9: Software software | E9: 79.49
A10: 45660 | B10: Gasolinera Autovía Norte | C10: Vehículos | D10: Vehículos gasolinera | E10: 415.59
A11: 45663 | B11: Gestoría Laboral Centro | C11: Servicios externos | D11: Servicios externos gestoría | E11: 227.28
A12: 45663 | B12: Subcontratas Montajes Ribera | C12: Subcontratas | D12: Subcontratas subcontratas | E12: 2945.04
A13: 45663 | B13: Renting Furgonetas Plus | C13: Vehículos | D13: Vehículos renting | E13: 931.27
... A2841: 46314 | B2841: Papelería Oficina Express | C2841: Oficina | D2841: Oficina papelería | E2841: 103.64

Sheet Resumen
A1: Mes | B1: Facturado (base) | C1: Gastos | D1: Margen | E1: Pendiente de cobro
A2: 45658 | B2: =SUMIFS(Facturas!$F$2:$F$2632,Facturas!$B$2:$B$2632,">="&A2,Facturas!$B$2:$B$2632,"<"&EDATE(A2,1)) -> 405643.09 | C2: =SUMIFS(Gastos!$E$2:$E$2841,Gastos!$A$2:$A$2841,">="&A2,Gastos!$A$2:$A$2841,"<"&EDATE(A2,1)) -> 208092.11 | D2: =IFERROR(B2-C2,0) -> 197550.98 | E2: 0
A3: 45689 | B3: =SUMIFS(Facturas!$F$2:$F$2632,Facturas!$B$2:$B$2632,">="&A3,Facturas!$B$2:$B$2632,"<"&EDATE(A3,1)) -> 370515.51 | C3: =SUMIFS(Gastos!$E$2:$E$2841,Gastos!$A$2:$A$2841,">="&A3,Gastos!$A$2:$A$2841,"<"&EDATE(A3,1)) -> 214140.52 | D3: =IFERROR(B3-C3,0) -> 156374.99 | E3: =SUMIFS(Facturas!$H$2:$H$2632,Facturas!$B$2:$B$2632,">="&A3,Facturas!$B$2:$B$2632,"<"&EDATE(A3,1),Facturas!$J$2:$J$2632,"<>Cobrada") -> 1953.44
A4: 45717 | B4: =SUMIFS(Facturas!$F$2:$F$2632,Facturas!$B$2:$B$2632,">="&A4,Facturas!$B$2:$B$2632,"<"&EDATE(A4,1)) -> 347842.25 | C4: =SUMIFS(Gastos!$E$2:$E$2841,Gastos!$A$2:$A$2841,">="&A4,Gastos!$A$2:$A$2841,"<"&EDATE(A4,1)) -> 221084.66 | D4: =IFERROR(B4-C4,0) -> 126757.59 | E4: =SUMIFS(Facturas!$H$2:$H$2632,Facturas!$B$2:$B$2632,">="&A4,Facturas!$B$2:$B$2632,"<"&EDATE(A4,1),Facturas!$J$2:$J$2632,"<>Cobrada") -> 14800.33
A5: 45748 | B5: =SUMIFS(Facturas!$F$2:$F$2632,Facturas!$B$2:$B$2632,">="&A5,Facturas!$B$2:$B$2632,"<"&EDATE(A5,1)) -> 480562.98 | C5: =SUMIFS(Gastos!$E$2:$E$2841,Gastos!$A$2:$A$2841,">="&A5,Gastos!$A$2:$A$2841,"<"&EDATE(A5,1)) -> 248536.79 | D5: =IFERROR(B5-C5,0) -> 232026.19 | E5: =SUMIFS(Facturas!$H$2:$H$2632,Facturas!$B$2:$B$2632,">="&A5,Facturas!$B$2:$B$2632,"<"&EDATE(A5,1),Facturas!$J$2:$J$2632,"<>Cobrada") -> 57287.46
A6: 45778 | B6: =SUMIFS(Facturas!$F$2:$F$2632,Facturas!$B$2:$B$2632,">="&A6,Facturas!$B$2:$B$2632,"<"&EDATE(A6,1)) -> 523389.07 | C6: =SUMIFS(Gastos!$E$2:$E$2841,Gastos!$A$2:$A$2841,">="&A6,Gastos!$A$2:$A$2841,"<"&EDATE(A6,1)) -> 272884.67 | D6: =IFERROR(B6-C6,0) -> 250504.4 | E6: =SUMIFS(Facturas!$H$2:$H$2632,Facturas!$B$2:$B$2632,">="&A6,Facturas!$B$2:$B$2632,"<"&EDATE(A6,1),Facturas!$J$2:$J$2632,"<>Cobrada") -> 529.27
A7: 45809 | B7: =SUMIFS(Facturas!$F$2:$F$2632,Facturas!$B$2:$B$2632,">="&A7,Facturas!$B$2:$B$2632,"<"&EDATE(A7,1)) -> 511595 | C7: =SUMIFS(Gastos!$E$2:$E$2841,Gastos!$A$2:$A$2841,">="&A7,Gastos!$A$2:$A$2841,"<"&EDATE(A7,1)) -> 315519.66 | D7: =IFERROR(B7-C7,0) -> 196075.34 | E7: 0
A8: 45839 | B8: =SUMIFS(Facturas!$F$2:$F$2632,Facturas!$B$2:$B$2632,">="&A8,Facturas!$B$2:$B$2632,"<"&EDATE(A8,1)) -> 322483.38 | C8: =SUMIFS(Gastos!$E$2:$E$2841,Gastos!$A$2:$A$2841,">="&A8,Gastos!$A$2:$A$2841,"<"&EDATE(A8,1)) -> 285198.81 | D8: =IFERROR(B8-C8,0) -> 37284.57 | E8: =SUMIFS(Facturas!$H$2:$H$2632,Facturas!$B$2:$B$2632,">="&A8,Facturas!$B$2:$B$2632,"<"&EDATE(A8,1),Facturas!$J$2:$J$2632,"<>Cobrada") -> 9306.45
A9: 45870 | B9: =SUMIFS(Facturas!$F$2:$F$2632,Facturas!$B$2:$B$2632,">="&A9,Facturas!$B$2:$B$2632,"<"&EDATE(A9,1)) -> 146360.24 | C9: =SUMIFS(Gastos!$E$2:$E$2841,Gastos!$A$2:$A$2841,">="&A9,Gastos!$A$2:$A$2841,"<"&EDATE(A9,1)) -> 126778.37 | D9: =IFERROR(B9-C9,0) -> 19581.87 | E9: =SUMIFS(Facturas!$H$2:$H$2632,Facturas!$B$2:$B$2632,">="&A9,Facturas!$B$2:$B$2632,"<"&EDATE(A9,1),Facturas!$J$2:$J$2632,"<>Cobrada") -> 7455.25
A10: 45901 | B10: =SUMIFS(Facturas!$F$2:$F$2632,Facturas!$B$2:$B$2632,">="&A10,Facturas!$B$2:$B$2632,"<"&EDATE(A10,1)) -> 493229.07 | C10: =SUMIFS(Gastos!$E$2:$E$2841,Gastos!$A$2:$A$2841,">="&A10,Gastos!$A$2:$A$2841,"<"&EDATE(A10,1)) -> 306806.17 | D10: =IFERROR(B10-C10,0) -> 186422.9 | E10: 0
A11: 45931 | B11: =SUMIFS(Facturas!$F$2:$F$2632,Facturas!$B$2:$B$2632,">="&A11,Facturas!$B$2:$B$2632,"<"&EDATE(A11,1)) -> 477255.27 | C11: =SUMIFS(Gastos!$E$2:$E$2841,Gastos!$A$2:$A$2841,">="&A11,Gastos!$A$2:$A$2841,"<"&EDATE(A11,1)) -> 318491.36 | D11: =IFERROR(B11-C11,0) -> 158763.91 | E11: =SUMIFS(Facturas!$H$2:$H$2632,Facturas!$B$2:$B$2632,">="&A11,Facturas!$B$2:$B$2632,"<"&EDATE(A11,1),Facturas!$J$2:$J$2632,"<>Cobrada") -> 6600.74
A12: 45962 | B12: =SUMIFS(Facturas!$F$2:$F$2632,Facturas!$B$2:$B$2632,">="&A12,Facturas!$B$2:$B$2632,"<"&EDATE(A12,1)) -> 349451.59 | C12: =SUMIFS(Gastos!$E$2:$E$2841,Gastos!$A$2:$A$2841,">="&A12,Gastos!$A$2:$A$2841,"<"&EDATE(A12,1)) -> 223137.02 | D12: =IFERROR(B12-C12,0) -> 126314.57 | E12: =SUMIFS(Facturas!$H$2:$H$2632,Facturas!$B$2:$B$2632,">="&A12,Facturas!$B$2:$B$2632,"<"&EDATE(A12,1),Facturas!$J$2:$J$2632,"<>Cobrada") -> 3963.51
A13: 45992 | B13: =SUMIFS(Facturas!$F$2:$F$2632,Facturas!$B$2:$B$2632,">="&A13,Facturas!$B$2:$B$2632,"<"&EDATE(A13,1)) -> 380835.95 | C13: =SUMIFS(Gastos!$E$2:$E$2841,Gastos!$A$2:$A$2841,">="&A13,Gastos!$A$2:$A$2841,"<"&EDATE(A13,1)) -> 224637.42 | D13: =IFERROR(B13-C13,0) -> 156198.53 | E13: 0
A14: 46023 | B14: =SUMIFS(Facturas!$F$2:$F$2632,Facturas!$B$2:$B$2632,">="&A14,Facturas!$B$2:$B$2632,"<"&EDATE(A14,1)) -> 274109.52 | C14: =SUMIFS(Gastos!$E$2:$E$2841,Gastos!$A$2:$A$2841,">="&A14,Gastos!$A$2:$A$2841,"<"&EDATE(A14,1)) -> 250111.85 | D14: =IFERROR(B14-C14,0) -> 23997.67 | E14: =SUMIFS(Facturas!$H$2:$H$2632,Facturas!$B$2:$B$2632,">="&A14,Facturas!$B$2:$B$2632,"<"&EDATE(A14,1),Facturas!$J$2:$J$2632,"<>Cobrada") -> 10144.36
A15: 46054 | B15: =SUMIFS(Facturas!$F$2:$F$2632,Facturas!$B$2:$B$2632,">="&A15,Facturas!$B$2:$B$2632,"<"&EDATE(A15,1)) -> 379532.64 | C15: =SUMIFS(Gastos!$E$2:$E$2841,Gastos!$A$2:$A$2841,">="&A15,Gastos!$A$2:$A$2841,"<"&EDATE(A15,1)) -> 223996.72 | D15: =IFERROR(B15-C15,0) -> 155535.92 | E15: =SUMIFS(Facturas!$H$2:$H$2632,Facturas!$B$2:$B$2632,">="&A15,Facturas!$B$2:$B$2632,"<"&EDATE(A15,1),Facturas!$J$2:$J$2632,"<>Cobrada") -> 812.89
A16: 46082 | B16: =SUMIFS(Facturas!$F$2:$F$2632,Facturas!$B$2:$B$2632,">="&A16,Facturas!$B$2:$B$2632,"<"&EDATE(A16,1)) -> 450018.98 | C16: =SUMIFS(Gastos!$E$2:$E$2841,Gastos!$A$2:$A$2841,">="&A16,Gastos!$A$2:$A$2841,"<"&EDATE(A16,1)) -> 257675.08 | D16: =IFERROR(B16-C16,0) -> 192343.9 | E16: 0
A17: 46113 | B17: =SUMIFS(Facturas!$F$2:$F$2632,Facturas!$B$2:$B$2632,">="&A17,Facturas!$B$2:$B$2632,"<"&EDATE(A17,1)) -> 486434.14 | C17: =SUMIFS(Gastos!$E$2:$E$2841,Gastos!$A$2:$A$2841,">="&A17,Gastos!$A$2:$A$2841,"<"&EDATE(A17,1)) -> 289261.25 | D17: =IFERROR(B17-C17,0) -> 197172.89 | E17: =SUMIFS(Facturas!$H$2:$H$2632,Facturas!$B$2:$B$2632,">="&A17,Facturas!$B$2:$B$2632,"<"&EDATE(A17,1),Facturas!$J$2:$J$2632,"<>Cobrada") -> 1739.98
A18: 46143 | B18: =SUMIFS(Facturas!$F$2:$F$2632,Facturas!$B$2:$B$2632,">="&A18,Facturas!$B$2:$B$2632,"<"&EDATE(A18,1)) -> 529218.48 | C18: =SUMIFS(Gastos!$E$2:$E$2841,Gastos!$A$2:$A$2841,">="&A18,Gastos!$A$2:$A$2841,"<"&EDATE(A18,1)) -> 270251.91 | D18: =IFERROR(B18-C18,0) -> 258966.57 | E18: 0
A19: 46174 | B19: =SUMIFS(Facturas!$F$2:$F$2632,Facturas!$B$2:$B$2632,">="&A19,Facturas!$B$2:$B$2632,"<"&EDATE(A19,1)) -> 591403.85 | C19: =SUMIFS(Gastos!$E$2:$E$2841,Gastos!$A$2:$A$2841,">="&A19,Gastos!$A$2:$A$2841,"<"&EDATE(A19,1)) -> 341286.74 | D19: =IFERROR(B19-C19,0) -> 250117.11 | E19: 0
A20: 46204 | B20: =SUMIFS(Facturas!$F$2:$F$2632,Facturas!$B$2:$B$2632,">="&A20,Facturas!$B$2:$B$2632,"<"&EDATE(A20,1)) -> 452865.79 | C20: =SUMIFS(Gastos!$E$2:$E$2841,Gastos!$A$2:$A$2841,">="&A20,Gastos!$A$2:$A$2841,"<"&EDATE(A20,1)) -> 352900.27 | D20: =IFERROR(B20-C20,0) -> 99965.52 | E20: =SUMIFS(Facturas!$H$2:$H$2632,Facturas!$B$2:$B$2632,">="&A20,Facturas!$B$2:$B$2632,"<"&EDATE(A20,1),Facturas!$J$2:$J$2632,"<>Cobrada") -> 436.94
A21: 46235 | B21: =SUMIFS(Facturas!$F$2:$F$2632,Facturas!$B$2:$B$2632,">="&A21,Facturas!$B$2:$B$2632,"<"&EDATE(A21,1)) -> 228680.71 | C21: =SUMIFS(Gastos!$E$2:$E$2841,Gastos!$A$2:$A$2841,">="&A21,Gastos!$A$2:$A$2841,"<"&EDATE(A21,1)) -> 109418.12 | D21: =IFERROR(B21-C21,0) -> 119262.59 | E21: =SUMIFS(Facturas!$H$2:$H$2632,Facturas!$B$2:$B$2632,">="&A21,Facturas!$B$2:$B$2632,"<"&EDATE(A21,1),Facturas!$J$2:$J$2632,"<>Cobrada") -> 32025.67
A22: 46266 | B22: =SUMIFS(Facturas!$F$2:$F$2632,Facturas!$B$2:$B$2632,">="&A22,Facturas!$B$2:$B$2632,"<"&EDATE(A22,1)) -> 601799.49 | C22: =SUMIFS(Gastos!$E$2:$E$2841,Gastos!$A$2:$A$2841,">="&A22,Gastos!$A$2:$A$2841,"<"&EDATE(A22,1)) -> 229884.92 | D22: =IFERROR(B22-C22,0) -> 371914.57 | E22: =SUMIFS(Facturas!$H$2:$H$2632,Facturas!$B$2:$B$2632,">="&A22,Facturas!$B$2:$B$2632,"<"&EDATE(A22,1),Facturas!$J$2:$J$2632,"<>Cobrada") -> 218490.28
A23: 46296 | B23: =SUMIFS(Facturas!$F$2:$F$2632,Facturas!$B$2:$B$2632,">="&A23,Facturas!$B$2:$B$2632,"<"&EDATE(A23,1)) -> 236480.12 | C23: =SUMIFS(Gastos!$E$2:$E$2841,Gastos!$A$2:$A$2841,">="&A23,Gastos!$A$2:$A$2841,"<"&EDATE(A23,1)) -> 196430.64 | D23: =IFERROR(B23-C23,0) -> 40049.48 | E23: =SUMIFS(Facturas!$H$2:$H$2632,Facturas!$B$2:$B$2632,">="&A23,Facturas!$B$2:$B$2632,"<"&EDATE(A23,1),Facturas!$J$2:$J$2632,"<>Cobrada") -> 161772.27
